<?xml version="1.0" encoding="utf-8"?>
<robot name="suii">

  <gazebo>
    <plugin name="ur3_plugin" filename="libur3_plugin.so"/>
  </gazebo>

  <gazebo>
    <plugin name="object_controller" filename="libgazebo_ros_planar_move.so">
      <commandTopic>cmd_vel</commandTopic>
      <odometryTopic>odom</odometryTopic>
      <odometryFrame>odom</odometryFrame>
      <odometryRate>20.0</odometryRate>
      <robotBaseFrame>base_link</robotBaseFrame>
    </plugin>
  </gazebo>

  <gazebo reference="lidar_front">
    <sensor type="ray" name="lidar_front">
      <pose>0 0 0 0 0 0</pose>
      <visualize>false</visualize>
      <update_rate>20</update_rate>
      <ray>
        <scan>
          <horizontal>
            <samples>720</samples>
            <resolution>1</resolution>
            <min_angle>-2.2661944902</min_angle>
            <max_angle>2.0943951024</max_angle>
          </horizontal>
        </scan>
        <range>
          <min>0.03</min>
          <max>10.0</max>
          <resolution>0.01</resolution>
        </range>
        <noise>
          <type>gaussian</type>
          <!-- Noise parameters based on published spec for Hokuyo laser
               achieving "+-30mm" accuracy at range < 10m.  A mean of 0.0m and
               stddev of 0.01m will put 99.7% of samples within 0.03m of the true
               reading. -->
          <mean>0.0</mean>
          <stddev>0.01</stddev>
        </noise>
      </ray>
      <plugin name="gazebo_ros_head_hokuyo_controller" filename="libgazebo_ros_laser.so">
        <topicName>/scan_front_real</topicName>
        <frameName>lidar_front</frameName>
      </plugin>
    </sensor>
  </gazebo>

  <gazebo reference="lidar_back">
    <sensor type="ray" name="lidar_back">
      <pose>0 0 0 0 0 0</pose>
      <visualize>false</visualize>
      <update_rate>20</update_rate>
      <ray>
        <scan>
          <horizontal>
            <samples>720</samples>
            <resolution>1</resolution>
            <min_angle>-2.2661944902</min_angle>
            <max_angle>2.0943951024</max_angle>
          </horizontal>
        </scan>
        <range>
          <min>0.03</min>
          <max>10.0</max>
          <resolution>0.01</resolution>
        </range>
        <noise>
          <type>gaussian</type>
          <!-- Noise parameters based on published spec for Hokuyo laser
               achieving "+-30mm" accuracy at range < 10m.  A mean of 0.0m and
               stddev of 0.01m will put 99.7% of samples within 0.03m of the true
               reading. -->
          <mean>0.0</mean>
          <stddev>0.01</stddev>
        </noise>
      </ray>
      <plugin name="gazebo_ros_head_hokuyo_controller" filename="libgazebo_ros_laser.so">
        <topicName>/scan_back_real</topicName>
        <frameName>lidar_back</frameName>
      </plugin>
    </sensor>
  </gazebo>

  <link name="base_link">
    <inertial>
      <origin rpy="0 0 0" xyz="0.00291234070014007 -1.66533453693773E-16 0.108047440506087"/>
      <mass value="100"/>
      <inertia ixx="1" ixy="0" ixz="0" iyy="1" iyz="0" izz="1"/>
    </inertial>
    <visual>
      <origin rpy="0 0 0" xyz="0 0 0"/>
      <geometry>
        <mesh filename="package://suii_description/meshes/base_link.STL"/>
      </geometry>
      <material name="">
        <color rgba="0.321568627 0.584313725 0.192156863 1"/>
      </material>
    </visual>
  </link>
  <link name="lidar_front">
    <inertial>
      <origin rpy="0 0 0" xyz="-0.00064881 3.9625E-06 -0.020287"/>
      <mass value="0.36783"/>
      <inertia ixx="0.00010865" ixy="3.8659E-08" ixz="-1.6811E-07" iyy="0.00011263" iyz="2.7923E-08" izz="3.9807E-06"/>
    </inertial>
    <visual>
      <origin rpy="0 0 0" xyz="0 0 0"/>
      <geometry>
        <mesh filename="package://suii_description/meshes/lidar_front.STL"/>
      </geometry>
      <material name="">
        <color rgba="0.1 0.1 0.1 1"/>
      </material>
    </visual>
  </link>
  <joint name="base_lidar_front" type="fixed">
    <origin rpy="0 0 0.785398163397448" xyz="0.236544996527457 0.173000674539992 0.22"/>
    <parent link="base_link"/>
    <child link="lidar_front"/>
    <axis xyz="0 0 0"/>
  </joint>
  <link name="lidar_back">
    <inertial>
      <origin rpy="0 0 0" xyz="-0.000648809624193947 3.96245467831902E-06 -0.0202872608509019"/>
      <mass value="0.36783371962175"/>
      <inertia ixx="0.000108647845447292" ixy="3.8658954336174E-08" ixz="-1.68113694814512E-07" iyy="0.00011262777703387" iyz="2.79229405729065E-08" izz="3.98071378579849E-06"/>
    </inertial>
    <visual>
      <origin rpy="0 0 0" xyz="0 0 0"/>
      <geometry>
        <mesh filename="package://suii_description/meshes/lidar_back.STL"/>
      </geometry>
      <material name="">
        <color rgba="0.1 0.1 0.1 1"/>
      </material>
    </visual>
  </link>
  <joint name="base_lidar_back" type="fixed">
    <origin rpy="0 0 -2.35619449019234" xyz="-0.239772970773009 -0.16977270029444 0.22"/>
    <parent link="base_link"/>
    <child link="lidar_back"/>
    <axis xyz="0 0 0"/>
  </joint>
  <link name="wheel_right_back">
    <inertial>
      <origin rpy="0 0 0" xyz="0 0 0.0935384610645182"/>
      <mass value="0.893028719302389"/>
      <inertia ixx="0" ixy="0" ixz="0" iyy="0" iyz="0" izz="0"/>
    </inertial>
    <visual>
      <origin rpy="0 0 0" xyz="0 0 0"/>
      <geometry>
        <mesh filename="package://suii_description/meshes/wheel_right_back.STL"/>
      </geometry>
      <material name="">
        <color rgba="0.792156862745098 0.819607843137255 0.933333333333333 1"/>
      </material>
    </visual>
    <collision>
      <origin rpy="0 0 0" xyz="0 0 0"/>
      <geometry>
        <mesh filename="package://suii_description/meshes/wheel_right_back.STL"/>
      </geometry>
    </collision>
  </link>
  <joint name="base_wheel_right_back" type="fixed">
    <origin rpy="1.5707963267949 -1.53833681942429 0" xyz="-0.154775 -0.0997000000000001 0.0750000000000002"/>
    <parent link="base_link"/>
    <child link="wheel_right_back"/>
    <axis xyz="0 0 0"/>
  </joint>
  <link name="wheel_right_front">
    <inertial>
      <origin rpy="0 0 0" xyz="5.55111512312578E-17 0 0.0935384610645182"/>
      <mass value="0.893028719302389"/>
      <inertia ixx="0" ixy="0" ixz="0" iyy="0" iyz="0" izz="0"/>
    </inertial>
    <visual>
      <origin rpy="0 0 0" xyz="0 0 0"/>
      <geometry>
        <mesh filename="package://suii_description/meshes/wheel_right_front.STL"/>
      </geometry>
      <material name="">
        <color rgba="0.792156862745098 0.819607843137255 0.933333333333333 1"/>
      </material>
    </visual>
    <collision>
      <origin rpy="0 0 0" xyz="0 0 0"/>
      <geometry>
        <mesh filename="package://suii_description/meshes/wheel_right_front.STL"/>
      </geometry>
    </collision>
  </link>
  <joint name="base_wheel_right_front" type="fixed">
    <origin rpy="1.5707963267949 0 0" xyz="0.154775 -0.0997000000000001 0.075"/>
    <parent link="base_link"/>
    <child link="wheel_right_front"/>
    <axis xyz="0 0 0"/>
  </joint>
  <link name="wheel_left_back">
    <inertial>
      <origin rpy="0 0 0" xyz="0 0 -0.0263815389354818"/>
      <mass value="0.893028719302389"/>
      <inertia ixx="0" ixy="0" ixz="0" iyy="0" iyz="0" izz="0"/>
    </inertial>
    <visual>
      <origin rpy="0 0 0" xyz="0 0 0"/>
      <geometry>
        <mesh filename="package://suii_description/meshes/wheel_left_back.STL"/>
      </geometry>
      <material name="">
        <color rgba="0.792156862745098 0.819607843137255 0.933333333333333 1"/>
      </material>
    </visual>
    <collision>
      <origin rpy="0 0 0" xyz="0 0 0"/>
      <geometry>
        <mesh filename="package://suii_description/meshes/wheel_left_back.STL"/>
      </geometry>
    </collision>
  </link>
  <joint name="base_wheel_left_back" type="fixed">
    <origin rpy="1.5707963267949 0.393094810426519 3.14159265358979" xyz="-0.154775 0.21962 0.075"/>
    <parent link="base_link"/>
    <child link="wheel_left_back"/>
    <axis xyz="0 0 0"/>
  </joint>
  <link name="wheel_left_front">
    <inertial>
      <origin rpy="0 0 0" xyz="0 0 -0.0263815389354819"/>
      <mass value="0.893028719302389"/>
      <inertia ixx="0" ixy="0" ixz="0" iyy="0" iyz="0" izz="0"/>
    </inertial>
    <visual>
      <origin rpy="0 0 0" xyz="0 0 0"/>
      <geometry>
        <mesh filename="package://suii_description/meshes/wheel_left_front.STL"/>
      </geometry>
      <material name="">
        <color rgba="0.792156862745098 0.819607843137255 0.933333333333333 1"/>
      </material>
    </visual>
    <collision>
      <origin rpy="0 0 0" xyz="0 0 0"/>
      <geometry>
        <mesh filename="package://suii_description/meshes/wheel_left_front.STL"/>
      </geometry>
    </collision>
  </link>
  <joint name="base_wheel_left_front" type="fixed">
    <origin rpy="1.5707963267949 0.393094810426517 3.14159265358979" xyz="0.154775 0.21962 0.075"/>
    <parent link="base_link"/>
    <child link="wheel_left_front"/>
    <axis xyz="0 0 0"/>
  </joint>
  <link name="arm_placeholder">
    <inertial>
      <origin rpy="0 0 0" xyz="-5.55111512312578E-17 0.005 -5.55111512312578E-17"/>
      <mass value="0.0031415926535898"/>
      <inertia ixx="0" ixy="0" ixz="0" iyy="0" iyz="0" izz="0"/>
    </inertial>
    <visual>
      <origin rpy="0 0 0" xyz="0 0 0"/>
      <geometry>
        <mesh filename="package://suii_description/meshes/arm_placeholder.STL"/>
      </geometry>
      <material name="">
        <color rgba="0.792156862745098 0.819607843137255 0.933333333333333 1"/>
      </material>
    </visual>
  </link>
  <joint name="base_arm" type="fixed">
    <origin rpy=" 0 0 0" xyz="0.20331 0 0.205"/>
    <!--1.5707963267949-->
    <parent link="base_link"/>
    <child link="arm_placeholder"/>
    <axis xyz="0 0 0"/>
  </joint>
  <joint name="arm_base_joint" type="fixed">
    <origin rpy="0.0 0.0 -1.5707963267949" xyz="0.0 0.0 0.0207767"/>
    <parent link="arm_placeholder"/>
    <child link="ur3/base_link"/>
  </joint>
  <link name="ur3/base_link">
    <visual>
      <geometry>
        <mesh filename="package://ur_description/meshes/ur3/visual/base.dae"/>
      </geometry>
      <material name="LightGrey">
        <color rgba="0.7 0.7 0.7 1.0"/>
      </material>
    </visual>
    <inertial>
      <mass value="1"/>
      <origin rpy="0 0 0" xyz="0.0 0.0 0.0"/>
      <inertia ixx="0.0030531654454" ixy="0.0" ixz="0.0" iyy="0.0030531654454" iyz="0.0" izz="0.005625"/>
    </inertial>
  </link>
  <joint name="ur3/shoulder_pan_joint" type="revolute">
    <parent link="ur3/base_link"/>
    <child link="ur3/shoulder_link"/>
    <origin rpy="0.0 0.0 0.0" xyz="0.0 0.0 0.1519"/>
    <axis xyz="0 0 1"/>
    <limit effort="330.0" lower="-6.28318530718" upper="6.28318530718" velocity="2.16"/>
    <dynamics damping="0.0" friction="0.0"/>
  </joint>
  <link name="ur3/shoulder_link">
    <visual>
      <geometry>
        <mesh filename="package://ur_description/meshes/ur3/visual/shoulder.dae"/>
      </geometry>
      <material name="LightGrey">
        <color rgba="0.7 0.7 0.7 1.0"/>
      </material>
    </visual>
    <inertial>
      <mass value="1"/>
      <origin rpy="0 0 0" xyz="0.0 0.0 0.0"/>
      <inertia ixx="0.0080931634294" ixy="0.0" ixz="0.0" iyy="0.0080931634294" iyz="0.0" izz="0.005625"/>
    </inertial>
  </link>
  <joint name="ur3/shoulder_lift_joint" type="revolute">
    <parent link="ur3/shoulder_link"/>
    <child link="ur3/upper_arm_link"/>
    <origin rpy="0.0 1.57079632679 0.0" xyz="0.0 0.1198 0.0"/>
    <axis xyz="0 1 0"/>
    <limit effort="330.0" lower="-6.28318530718" upper="6.28318530718" velocity="2.16"/>
    <dynamics damping="0.0" friction="0.0"/>
  </joint>
  <link name="ur3/upper_arm_link">
    <visual>
      <geometry>
        <mesh filename="package://ur_description/meshes/ur3/visual/upperarm.dae"/>
      </geometry>
      <material name="LightGrey">
        <color rgba="0.7 0.7 0.7 1.0"/>
      </material>
    </visual>
    <inertial>
      <mass value="1.0"/>
      <origin rpy="0 0 0" xyz="0.0 0.0 0.121825"/>
      <inertia ixx="0.0217284832211" ixy="0.0" ixz="0.0" iyy="0.0217284832211" iyz="0.0" izz="0.00961875"/>
    </inertial>
  </link>
  <joint name="ur3/elbow_joint" type="revolute">
    <parent link="ur3/upper_arm_link"/>
    <child link="ur3/forearm_link"/>
    <origin rpy="0.0 0.0 0.0" xyz="0.0 -0.0925 0.24365"/>
    <axis xyz="0 1 0"/>
    <limit effort="150.0" lower="-3.14159265359" upper="3.14159265359" velocity="3.15"/>
    <dynamics damping="0.0" friction="0.0"/>
  </joint>
  <link name="ur3/forearm_link">
    <visual>
      <geometry>
        <mesh filename="package://ur_description/meshes/ur3/visual/forearm.dae"/>
      </geometry>
      <material name="LightGrey">
        <color rgba="0.7 0.7 0.7 1.0"/>
      </material>
    </visual>
    <inertial>
      <mass value="1"/>
      <origin rpy="0 0 0" xyz="0.0 0.0 0.106625"/>
      <inertia ixx="0.00654680644378" ixy="0.0" ixz="0.0" iyy="0.00654680644378" iyz="0.0" izz="0.00354375"/>
    </inertial>
  </link>
  <joint name="ur3/wrist_1_joint" type="revolute">
    <parent link="ur3/forearm_link"/>
    <child link="ur3/wrist_1_link"/>
    <origin rpy="0.0 1.57079632679 0.0" xyz="0.0 0.0 0.21325"/>
    <axis xyz="0 1 0"/>
    <limit effort="54.0" lower="-6.28318530718" upper="6.28318530718" velocity="3.2"/>
    <dynamics damping="0.0" friction="0.0"/>
  </joint>
  <link name="ur3/wrist_1_link">
    <visual>
      <geometry>
        <mesh filename="package://ur_description/meshes/ur3/visual/wrist1.dae"/>
      </geometry>
      <material name="LightGrey">
        <color rgba="0.7 0.7 0.7 1.0"/>
      </material>
    </visual>
    <inertial>
      <mass value="0.8"/>
      <origin rpy="0 0 0" xyz="0.0 0.0 0.0"/>
      <inertia ixx="0.002084999166" ixy="0.0" ixz="0.0" iyy="0.002084999166" iyz="0.0" izz="0.00225"/>
    </inertial>
  </link>
  <joint name="ur3/wrist_2_joint" type="revolute">
    <parent link="ur3/wrist_1_link"/>
    <child link="ur3/wrist_2_link"/>
    <origin rpy="0.0 0.0 0.0" xyz="0.0 0.08505 0.0"/>
    <axis xyz="0 0 1"/>
    <limit effort="54.0" lower="-6.28318530718" upper="6.28318530718" velocity="3.2"/>
    <dynamics damping="0.0" friction="0.0"/>
  </joint>
  <link name="ur3/wrist_2_link">
    <visual>
      <geometry>
        <mesh filename="package://ur_description/meshes/ur3/visual/wrist2.dae"/>
      </geometry>
      <material name="LightGrey">
        <color rgba="0.7 0.7 0.7 1.0"/>
      </material>
    </visual>
    <inertial>
      <mass value="0.8"/>
      <origin rpy="0 0 0" xyz="0.0 0.0 0.0"/>
      <inertia ixx="0.002084999166" ixy="0.0" ixz="0.0" iyy="0.002084999166" iyz="0.0" izz="0.00225"/>
    </inertial>
  </link>
  <joint name="ur3/wrist_3_joint" type="revolute">
    <parent link="ur3/wrist_2_link"/>
    <child link="ur3/wrist_3_link"/>
    <origin rpy="0.0 0.0 0.0" xyz="0.0 0.0 0.08535"/>
    <axis xyz="0 1 0"/>
    <limit effort="54.0" lower="-6.28318530718" upper="6.28318530718" velocity="3.2"/>
    <dynamics damping="0.0" friction="0.0"/>
  </joint>
  <link name="ur3/wrist_3_link">
    <visual>
      <geometry>
        <mesh filename="package://ur_description/meshes/ur3/visual/wrist3.dae"/>
      </geometry>
      <material name="LightGrey">
        <color rgba="0.7 0.7 0.7 1.0"/>
      </material>
    </visual>
    <inertial>
      <mass value="0.35"/>
      <origin rpy="0 0 0" xyz="0.0 0.0 0.0"/>
      <inertia ixx="0.000912187135125" ixy="0.0" ixz="0.0" iyy="0.000912187135125" iyz="0.0" izz="0.000984375"/>
    </inertial>
  </link>
  <joint name="ur3/ee_fixed_joint" type="fixed">
    <parent link="ur3/wrist_3_link"/>
    <child link="ur3/ee_link"/>
    <origin rpy="0.0 0.0 1.57079632679" xyz="0.0 0.0819 0.0"/>
  </joint>
  <link name="ur3/ee_link">
  </link>

  <link name="ur3/base"/>
  <joint name="ur3/base_link-base_fixed_joint" type="fixed">

    <origin rpy="0 0 -3.14159265359" xyz="0 0 0"/>
    <parent link="ur3/base_link"/>
    <child link="ur3/base"/>
  </joint>

  <link name="ur3/tool0"/>
  <joint name="ur3/wrist_3_link-tool0_fixed_joint" type="fixed">
    <origin rpy="-1.57079632679 0 0" xyz="0 0.0819 0"/>
    <parent link="ur3/wrist_3_link"/>
    <child link="ur3/tool0"/>
  </joint>

  <joint name="camera_joint" type="fixed">
    <origin xyz="0 -0.044877 0.105" rpy="0 -1.57079632679 1.57079632679"/>
    <parent link="ur3/tool0"/>
    <child link="camera_placeholder"/>
  </joint>

  <link name="camera_placeholder">

    <visual>
      <origin xyz="0 0 0" rpy="0 0 0"/>
      <geometry>
        <box size="0.005 0.005 0.005"/>
      </geometry>
    </visual>

    <inertial>
      <origin rpy="0 0 0" xyz="0.0 0.0 0.0"/>
      <mass value="0.001" />
      <inertia ixx="0.001" ixy="0" ixz="0" iyy="0.001" iyz="0" izz="0.001" />
    </inertial>
  </link>
  <joint name="gripper_attachment" type="fixed">
    <origin rpy="3.1416 0 3.1416" xyz="0 0 0"/>
    <parent link="ur3/tool0"/>
    <child link="gripper"/>
  </joint>
  <link
    name="gripper">
    <inertial>
      <origin
        xyz="0.000314385625916895 -0.0110896096035867 -0.0421598850024997"
        rpy="0 0 0" />
      <mass
        value="1.15466628725613" />
      <inertia
        ixx="0.00103353968597952"
        ixy="-7.91796963434665E-06"
        ixz="4.82839117797138E-06"
        iyy="0.000848364176880939"
        iyz="-0.000235749466056584"
        izz="0.000667207579525162" />
    </inertial>
    <visual>
      <origin
        xyz="0 0 0"
        rpy="0 0 0" />
      <geometry>
        <mesh
          filename="package://suii_simulation/meshes/base_link.STL" />
      </geometry>
      <material
        name="">
        <color
          rgba="0.898039215686275 0.917647058823529 0.929411764705882 1" />
      </material>
    </visual>
    <collision>
      <origin
        xyz="0 0 0"
        rpy="0 0 0" />
      <geometry>
        <mesh
          filename="package://suii_simulation/meshes/base_link.STL" />
      </geometry>
    </collision>
  </link>
  <link
    name="servo_link">
    <inertial>
      <origin
        xyz="3.58979339309951E-16 0.0122205346294046 -6.93889390390723E-18"
        rpy="0 0 0" />
      <mass
        value="0.00361974305546616" />
      <inertia
        ixx="0"
        ixy="0"
        ixz="0"
        iyy="0"
        iyz="0"
        izz="0" />
    </inertial>
    <visual>
      <origin
        xyz="0 0 0"
        rpy="0 0 0" />
      <geometry>
        <mesh
          filename="package://suii_simulation/meshes/servo_link.STL" />
      </geometry>
      <material
        name="">
        <color
          rgba="0.792156862745098 0.819607843137255 0.933333333333333 1" />
      </material>
    </visual>
    <collision>
      <origin
        xyz="0 0 0"
        rpy="0 0 0" />
      <geometry>
        <mesh
          filename="package://suii_simulation/meshes/servo_link.STL" />
      </geometry>
    </collision>
  </link>
  <joint
    name="servo"
    type="continuous">
    <origin
      xyz="-0.02175 0.01426 -0.0285"
      rpy="0 0 3.1416" />
    <parent
      link="gripper" />
    <child
      link="servo_link" />
    <axis
      xyz="0 1 0" />
  </joint>
  <link
    name="rightTilted_link">
    <inertial>
      <origin
        xyz="0.0362280758621729 -0.00440456680250059 -0.00401068190727637"
        rpy="0 0 0" />
      <mass
        value="0.034397394962144" />
      <inertia
        ixx="0"
        ixy="0"
        ixz="0"
        iyy="0"
        iyz="0"
        izz="0" />
    </inertial>
    <visual>
      <origin
        xyz="0 0 0"
        rpy="0 0 0" />
      <geometry>
        <mesh
          filename="package://suii_simulation/meshes/rightTilted_link.STL" />
      </geometry>
      <material
        name="">
        <color
          rgba="0.898039215686275 0.917647058823529 0.929411764705882 1" />
      </material>
    </visual>
    <collision>
      <origin
        xyz="0 0 0"
        rpy="0 0 0" />
      <geometry>
        <mesh
          filename="package://suii_simulation/meshes/rightTilted_link.STL" />
      </geometry>
    </collision>
  </link>
  <joint
    name="rightTilted"
    type="continuous">
    <origin
      xyz="-0.04625 0.0035 -0.041"
      rpy="0 0 3.1416" />
    <parent
      link="gripper" />
    <child
      link="rightTilted_link" />
    <axis
      xyz="0 1 0" />
  </joint>
  <link
    name="rightStraight_ink">
    <inertial>
      <origin
        xyz="0.031803880095001 -0.00383013954258074 -0.00624412256539431"
        rpy="0 0 0" />
      <mass
        value="0.0412389600755427" />
      <inertia
        ixx="0"
        ixy="0"
        ixz="0"
        iyy="0"
        iyz="0"
        izz="0" />
    </inertial>
    <visual>
      <origin
        xyz="0 0 0"
        rpy="0 0 0" />
      <geometry>
        <mesh
          filename="package://suii_simulation/meshes/rightStraight_ink.STL" />
      </geometry>
      <material
        name="">
        <color
          rgba="0.898039215686275 0.917647058823529 0.929411764705882 1" />
      </material>
    </visual>
    <collision>
      <origin
        xyz="0 0 0"
        rpy="0 0 0" />
      <geometry>
        <mesh
          filename="package://suii_simulation/meshes/rightStraight_ink.STL" />
      </geometry>
    </collision>
  </link>
  <joint
    name="rightStraight"
    type="continuous">
    <origin
      xyz="-0.02125 0.0035 -0.061"
      rpy="0 0 3.1416" />
    <parent
      link="gripper" />
    <child
      link="rightStraight_ink" />
    <axis
      xyz="0 1 0" />
  </joint>
  <link
    name="fingerRightLeft_link">
    <inertial>
      <origin
        xyz="0.00267701171751486 -3.57353036051222E-16 -0.00353142500094274"
        rpy="0 0 0" />
      <mass
        value="0.0360851632485204" />
      <inertia
        ixx="5.73730897263212E-06"
        ixy="5.17734697967733E-20"
        ixz="-2.49725703207321E-06"
        iyy="6.82428070693948E-06"
        iyz="1.18946663877336E-19"
        izz="1.08697173430736E-06" />
    </inertial>
    <visual>
      <origin
        xyz="0 0 0"
        rpy="0 0 0" />
      <geometry>
        <mesh
          filename="package://suii_simulation/meshes/fingerRightLeft_link.STL" />
      </geometry>
      <material
        name="">
        <color
          rgba="0.898039215686275 0.917647058823529 0.929411764705882 1" />
      </material>
    </visual>
    <collision>
      <origin
        xyz="0 0 0"
        rpy="0 0 0" />
      <geometry>
        <mesh
          filename="package://suii_simulation/meshes/fingerRightLeft_link.STL" />
      </geometry>
    </collision>
  </link>
  <joint
    name="fingerRightLeft_link2"
    type="continuous">
    <origin
      xyz="0.083548 0 -0.010487"
      rpy="0 0 0" />
    <parent
      link="rightStraight_ink" />
    <child
      link="fingerRightLeft_link" />
    <axis
      xyz="0 1 0" />
  </joint>
  <link
    name="leftStraight_link">
    <inertial>
      <origin
        xyz="-0.0317914966065302 -0.00383013974586561 -0.00630685637830356"
        rpy="0 0 0" />
      <mass
        value="0.0412389650707455" />
      <inertia
        ixx="0"
        ixy="0"
        ixz="0"
        iyy="0"
        iyz="0"
        izz="0" />
    </inertial>
    <visual>
      <origin
        xyz="0 0 0"
        rpy="0 0 0" />
      <geometry>
        <mesh
          filename="package://suii_simulation/meshes/leftStraight_link.STL" />
      </geometry>
      <material
        name="">
        <color
          rgba="0.898039215686275 0.917647058823529 0.929411764705882 1" />
      </material>
    </visual>
    <collision>
      <origin
        xyz="0 0 0"
        rpy="0 0 0" />
      <geometry>
        <mesh
          filename="package://suii_simulation/meshes/leftStraight_link.STL" />
      </geometry>
    </collision>
  </link>
  <joint
    name="leftStraight"
    type="continuous">
    <origin
      xyz="0.02125 0.0035 -0.061"
      rpy="0 0 3.1416" />
    <parent
      link="gripper" />
    <child
      link="leftStraight_link" />
    <axis
      xyz="0 1 0" />
  </joint>
  <link
    name="leftTilted_link">
    <inertial>
      <origin
        xyz="-0.0362280758621757 -0.00440456680250058 -0.00401068190727924"
        rpy="0 0 0" />
      <mass
        value="0.0343973949621441" />
      <inertia
        ixx="0"
        ixy="0"
        ixz="0"
        iyy="0"
        iyz="0"
        izz="0" />
    </inertial>
    <visual>
      <origin
        xyz="0 0 0"
        rpy="0 0 0" />
      <geometry>
        <mesh
          filename="package://suii_simulation/meshes/leftTilted_link.STL" />
      </geometry>
      <material
        name="">
        <color
          rgba="0.898039215686275 0.917647058823529 0.929411764705882 1" />
      </material>
    </visual>
    <collision>
      <origin
        xyz="0 0 0"
        rpy="0 0 0" />
      <geometry>
        <mesh
          filename="package://suii_simulation/meshes/leftTilted_link.STL" />
      </geometry>
    </collision>
  </link>
  <joint
    name="leftTilted"
    type="continuous">
    <origin
      xyz="0.04625 0.0035 -0.041"
      rpy="0 0 3.1416" />
    <parent
      link="gripper" />
    <child
      link="leftTilted_link" />
    <axis
      xyz="0 1 0" />
  </joint>
  <link
    name="fingerLeftLeft_link">
    <inertial>
      <origin
        xyz="-0.00256530007946196 0 -0.00350460540950224"
        rpy="0 0 0" />
      <mass
        value="0.0360851632485204" />
      <inertia
        ixx="5.70407821437543E-06"
        ixy="1.34709832417505E-21"
        ixz="2.55912194503496E-06"
        iyy="6.85222255662068E-06"
        iyz="-3.00257446443943E-21"
        izz="1.14814434224524E-06" />
    </inertial>
    <visual>
      <origin
        xyz="0 0 0"
        rpy="0 0 0" />
      <geometry>
        <mesh
          filename="package://suii_simulation/meshes/fingerLeftLeft_link.STL" />
      </geometry>
      <material
        name="">
        <color
          rgba="0.898039215686275 0.917647058823529 0.929411764705882 1" />
      </material>
    </visual>
    <collision>
      <origin
        xyz="0 0 0"
        rpy="0 0 0" />
      <geometry>
        <mesh
          filename="package://suii_simulation/meshes/fingerLeftLeft_link.STL" />
      </geometry>
    </collision>
  </link>
  <joint
    name="fingerLeftLeft"
    type="continuous">
    <origin
      xyz="-0.058548 0 -0.030487"
      rpy="0 0 0" />
    <parent
      link="leftTilted_link" />
    <child
      link="fingerLeftLeft_link" />
    <axis
      xyz="0 1 0" />
  </joint>

  <gazebo reference="camera_placeholder">
  <sensor name="camera" type="depth">
    <update_rate>10</update_rate>
    <camera>
      <horizontal_fov>1.047198</horizontal_fov>
      <image>
        <width>640</width>
        <height>480</height>
        <format>R8G8B8</format>
      </image>
      <clip>
        <near>0.05</near>
        <far>3</far>
      </clip>
    </camera>
    <plugin name="kinect" filename="libgazebo_ros_openni_kinect.so">
      <baseline>0.2</baseline>
      <alwaysOn>true</alwaysOn>
      <updateRate>1.0</updateRate>
      <cameraName>camera</cameraName>
      <imageTopicName>/camera/color/image_raw</imageTopicName>
      <cameraInfoTopicName>/camera/color/camera_info</cameraInfoTopicName>
      <depthImageTopicName>/camera/depth/image_raw</depthImageTopicName>
      <depthImageInfoTopicName>/camera/depth/camera_info</depthImageInfoTopicName>
      <pointCloudTopicName>/camera/depth/points</pointCloudTopicName>
      <frameName>camera</frameName>
      <pointCloudCutoff>0.05</pointCloudCutoff>
      <pointCloudCutoffMax>3.0</pointCloudCutoffMax>
      <distortionK1>0.00000001</distortionK1>
      <distortionK2>0.00000001</distortionK2>
      <distortionK3>0.00000001</distortionK3>
      <distortionT1>0.00000001</distortionT1>
      <distortionT2>0.00000001</distortionT2>
      <CxPrime>0</CxPrime>
      <Cx>0</Cx>
      <Cy>0</Cy>
      <focalLength>0</focalLength>
      <hackBaseline>0</hackBaseline>
    </plugin>
  </sensor>
  </gazebo>

  <gazebo reference="base_link">
    <material>Gazebo/Green</material>
    <kinematic>true</kinematic>
  </gazebo>

  <gazebo reference="wheel_right_front">
    <material>Gazebo/Red</material>
      <collision>
        <surface>
          <friction>
            <ode>
              <mu>1</mu>
              <mu2>1</mu2>
              <slip1>1.0</slip1>
              <slip2>1.0</slip2>
            </ode>
          </friction>
        </surface>
      </collsion>
  </gazebo>
  
  <gazebo reference="wheel_right_back">
    <material>Gazebo/Red</material>
      <collision>
        <surface>
          <friction>
            <ode>
              <mu>1</mu>
              <mu2>1</mu2>
              <slip1>1.0</slip1>
              <slip2>1.0</slip2>
            </ode>
          </friction>
        </surface>
      </collsion>
  </gazebo>

  <gazebo reference="wheel_left_front">
    <material>Gazebo/Red</material>
      <collision>
        <surface>
          <friction>
            <ode>
              <mu>1</mu>
              <mu2>1</mu2>
              <slip1>1.0</slip1>
              <slip2>1.0</slip2>
            </ode>
          </friction>
        </surface>
      </collsion>
  </gazebo>

  <gazebo reference="wheel_left_back">
    <material>Gazebo/Red</material>
      <collision>
        <surface>
          <friction>
            <ode>
              <mu>1</mu>
              <mu2>1</mu2>
              <slip1>1.0</slip1>
              <slip2>1.0</slip2>
            </ode>
          </friction>
        </surface>
      </collsion>
  </gazebo>

  <gazebo reference="lidar_front">
    <material>Gazebo/Orange</material>
  </gazebo>
  <gazebo reference="lidar_back">
    <material>Gazebo/Orange</material>
  </gazebo>

</robot>
